[2024-07-07T19:02:27.610+0000] {local_task_job_runner.py:120} INFO - ::group::Pre task execution logs
[2024-07-07T19:02:27.625+0000] {taskinstance.py:2076} INFO - Dependencies all met for dep_context=non-requeueable deps ti=<TaskInstance: chess_etl.redshift_move_load backfill__2019-03-01T00:00:00+00:00 [queued]>
[2024-07-07T19:02:27.630+0000] {taskinstance.py:2076} INFO - Dependencies all met for dep_context=requeueable deps ti=<TaskInstance: chess_etl.redshift_move_load backfill__2019-03-01T00:00:00+00:00 [queued]>
[2024-07-07T19:02:27.631+0000] {taskinstance.py:2306} INFO - Starting attempt 1 of 1
[2024-07-07T19:02:27.643+0000] {taskinstance.py:2330} INFO - Executing <Task(PythonOperator): redshift_move_load> on 2019-03-01 00:00:00+00:00
[2024-07-07T19:02:27.650+0000] {warnings.py:110} WARNING - /home/***/.local/lib/python3.12/site-packages/***/task/task_runner/standard_task_runner.py:61: DeprecationWarning: This process (pid=104) is multi-threaded, use of fork() may lead to deadlocks in the child.
  pid = os.fork()

[2024-07-07T19:02:27.651+0000] {standard_task_runner.py:90} INFO - Running: ['***', 'tasks', 'run', 'chess_etl', 'redshift_move_load', 'backfill__2019-03-01T00:00:00+00:00', '--job-id', '493', '--pool', 'default_pool', '--raw', '--subdir', 'DAGS_FOLDER/chess_dag.py', '--cfg-path', '/tmp/tmpk0ed4ci1']
[2024-07-07T19:02:27.652+0000] {standard_task_runner.py:63} INFO - Started process 110 to run task
[2024-07-07T19:02:27.652+0000] {standard_task_runner.py:91} INFO - Job 493: Subtask redshift_move_load
[2024-07-07T19:02:27.683+0000] {task_command.py:426} INFO - Running <TaskInstance: chess_etl.redshift_move_load backfill__2019-03-01T00:00:00+00:00 [running]> on host 1c777a41c043
[2024-07-07T19:02:27.745+0000] {taskinstance.py:2648} INFO - Exporting env vars: AIRFLOW_CTX_DAG_OWNER='***' AIRFLOW_CTX_DAG_ID='chess_etl' AIRFLOW_CTX_TASK_ID='redshift_move_load' AIRFLOW_CTX_EXECUTION_DATE='2019-03-01T00:00:00+00:00' AIRFLOW_CTX_TRY_NUMBER='1' AIRFLOW_CTX_DAG_RUN_ID='backfill__2019-03-01T00:00:00+00:00'
[2024-07-07T19:02:27.746+0000] {taskinstance.py:430} INFO - ::endgroup::
[2024-07-07T19:02:27.747+0000] {warnings.py:110} WARNING - /home/***/.local/lib/python3.12/site-packages/***/utils/context.py:320: AirflowContextDeprecationWarning: Accessing 'execution_date' from the template is deprecated and will be removed in a future version. Please use 'data_interval_start' or 'logical_date' instead.
  warnings.warn(_create_deprecation_warning(k, replacements))

[2024-07-07T19:02:27.752+0000] {base.py:84} INFO - Using connection ID 'chess_project_s3' for task execution.
[2024-07-07T19:02:28.606+0000] {base.py:84} INFO - Using connection ID 'chess_project_redshift' for task execution.
[2024-07-07T19:02:30.219+0000] {taskinstance.py:441} INFO - ::group::Post task execution logs
[2024-07-07T19:02:30.219+0000] {taskinstance.py:2905} ERROR - Task failed with exception
Traceback (most recent call last):
  File "/home/airflow/.local/lib/python3.12/site-packages/redshift_connector/core.py", line 1821, in execute
    ps = cache["ps"][key]
         ~~~~~~~~~~~^^^^^
KeyError: ('\n    DELETE FROM "dev"."chess_project"."move"\n    WHERE monthstart = date \'2019-03-01 00:00:00+00:00\'\n    ;\n    ', ())

During handling of the above exception, another exception occurred:

Traceback (most recent call last):
  File "/home/airflow/.local/lib/python3.12/site-packages/airflow/models/taskinstance.py", line 465, in _execute_task
    result = _execute_callable(context=context, **execute_callable_kwargs)
             ^^^^^^^^^^^^^^^^^^^^^^^^^^^^^^^^^^^^^^^^^^^^^^^^^^^^^^^^^^^^^
  File "/home/airflow/.local/lib/python3.12/site-packages/airflow/models/taskinstance.py", line 432, in _execute_callable
    return execute_callable(context=context, **execute_callable_kwargs)
           ^^^^^^^^^^^^^^^^^^^^^^^^^^^^^^^^^^^^^^^^^^^^^^^^^^^^^^^^^^^^
  File "/home/airflow/.local/lib/python3.12/site-packages/airflow/models/baseoperator.py", line 400, in wrapper
    return func(self, *args, **kwargs)
           ^^^^^^^^^^^^^^^^^^^^^^^^^^^
  File "/home/airflow/.local/lib/python3.12/site-packages/airflow/operators/python.py", line 235, in execute
    return_value = self.execute_callable()
                   ^^^^^^^^^^^^^^^^^^^^^^^
  File "/home/airflow/.local/lib/python3.12/site-packages/airflow/operators/python.py", line 252, in execute_callable
    return self.python_callable(*self.op_args, **self.op_kwargs)
           ^^^^^^^^^^^^^^^^^^^^^^^^^^^^^^^^^^^^^^^^^^^^^^^^^^^^^
  File "/opt/airflow/dags/chess_dag.py", line 31, in redshift_move_task
    return load_move_data(execution_date)
           ^^^^^^^^^^^^^^^^^^^^^^^^^^^^^^
  File "/opt/airflow/dags/redshift_etl_code.py", line 211, in load_move_data
    cursor.execute(delete_moves_query)
  File "/home/airflow/.local/lib/python3.12/site-packages/redshift_connector/cursor.py", line 248, in execute
    raise e
  File "/home/airflow/.local/lib/python3.12/site-packages/redshift_connector/cursor.py", line 241, in execute
    self._c.execute(self, operation, args)
  File "/home/airflow/.local/lib/python3.12/site-packages/redshift_connector/core.py", line 1902, in execute
    self.handle_messages(cursor)
  File "/home/airflow/.local/lib/python3.12/site-packages/redshift_connector/core.py", line 2194, in handle_messages
    raise self.error
redshift_connector.error.ProgrammingError: {'S': 'ERROR', 'C': '42703', 'M': 'column "monthstart" does not exist in move', 'F': '../src/pg/src/backend/parser/parse_expr.c', 'L': '1944', 'R': 'transformColumnRef'}
[2024-07-07T19:02:30.227+0000] {taskinstance.py:1206} INFO - Marking task as FAILED. dag_id=chess_etl, task_id=redshift_move_load, run_id=backfill__2019-03-01T00:00:00+00:00, execution_date=20190301T000000, start_date=20240707T190227, end_date=20240707T190230
[2024-07-07T19:02:30.235+0000] {standard_task_runner.py:110} ERROR - Failed to execute job 493 for task redshift_move_load ({'S': 'ERROR', 'C': '42703', 'M': 'column "monthstart" does not exist in move', 'F': '../src/pg/src/backend/parser/parse_expr.c', 'L': '1944', 'R': 'transformColumnRef'}; 110)
[2024-07-07T19:02:30.272+0000] {local_task_job_runner.py:240} INFO - Task exited with return code 1
[2024-07-07T19:02:30.285+0000] {taskinstance.py:3498} INFO - 0 downstream tasks scheduled from follow-on schedule check
[2024-07-07T19:02:30.286+0000] {local_task_job_runner.py:222} INFO - ::endgroup::
[2024-07-07T21:05:22.899+0000] {local_task_job_runner.py:120} INFO - ::group::Pre task execution logs
[2024-07-07T21:05:22.913+0000] {taskinstance.py:2076} INFO - Dependencies all met for dep_context=non-requeueable deps ti=<TaskInstance: chess_etl.redshift_move_load backfill__2019-03-01T00:00:00+00:00 [queued]>
[2024-07-07T21:05:22.918+0000] {taskinstance.py:2076} INFO - Dependencies all met for dep_context=requeueable deps ti=<TaskInstance: chess_etl.redshift_move_load backfill__2019-03-01T00:00:00+00:00 [queued]>
[2024-07-07T21:05:22.919+0000] {taskinstance.py:2306} INFO - Starting attempt 1 of 1
[2024-07-07T21:05:22.931+0000] {taskinstance.py:2330} INFO - Executing <Task(PythonOperator): redshift_move_load> on 2019-03-01 00:00:00+00:00
[2024-07-07T21:05:22.937+0000] {warnings.py:110} WARNING - /home/***/.local/lib/python3.12/site-packages/***/task/task_runner/standard_task_runner.py:61: DeprecationWarning: This process (pid=845) is multi-threaded, use of fork() may lead to deadlocks in the child.
  pid = os.fork()

[2024-07-07T21:05:22.938+0000] {standard_task_runner.py:63} INFO - Started process 847 to run task
[2024-07-07T21:05:22.938+0000] {standard_task_runner.py:90} INFO - Running: ['***', 'tasks', 'run', 'chess_etl', 'redshift_move_load', 'backfill__2019-03-01T00:00:00+00:00', '--job-id', '543', '--pool', 'default_pool', '--raw', '--subdir', 'DAGS_FOLDER/chess_dag.py', '--cfg-path', '/tmp/tmpakc4ztmc']
[2024-07-07T21:05:22.939+0000] {standard_task_runner.py:91} INFO - Job 543: Subtask redshift_move_load
[2024-07-07T21:05:22.976+0000] {task_command.py:426} INFO - Running <TaskInstance: chess_etl.redshift_move_load backfill__2019-03-01T00:00:00+00:00 [running]> on host 6569f5155f0c
[2024-07-07T21:05:23.037+0000] {taskinstance.py:2648} INFO - Exporting env vars: AIRFLOW_CTX_DAG_OWNER='***' AIRFLOW_CTX_DAG_ID='chess_etl' AIRFLOW_CTX_TASK_ID='redshift_move_load' AIRFLOW_CTX_EXECUTION_DATE='2019-03-01T00:00:00+00:00' AIRFLOW_CTX_TRY_NUMBER='1' AIRFLOW_CTX_DAG_RUN_ID='backfill__2019-03-01T00:00:00+00:00'
[2024-07-07T21:05:23.038+0000] {taskinstance.py:430} INFO - ::endgroup::
[2024-07-07T21:05:23.039+0000] {warnings.py:110} WARNING - /home/***/.local/lib/python3.12/site-packages/***/utils/context.py:320: AirflowContextDeprecationWarning: Accessing 'execution_date' from the template is deprecated and will be removed in a future version. Please use 'data_interval_start' or 'logical_date' instead.
  warnings.warn(_create_deprecation_warning(k, replacements))

[2024-07-07T21:05:23.045+0000] {base.py:84} INFO - Using connection ID 'chess_project_s3' for task execution.
[2024-07-07T21:05:23.888+0000] {base.py:84} INFO - Using connection ID 'chess_project_redshift' for task execution.
[2024-07-07T21:05:24.517+0000] {taskinstance.py:441} INFO - ::group::Post task execution logs
[2024-07-07T21:05:24.518+0000] {taskinstance.py:2905} ERROR - Task failed with exception
Traceback (most recent call last):
  File "/home/airflow/.local/lib/python3.12/site-packages/redshift_connector/core.py", line 1821, in execute
    ps = cache["ps"][key]
         ~~~~~~~~~~~^^^^^
KeyError: ('\n    DELETE FROM "dev"."chess_project_staging"."move"\n    WHERE dateid >= date \'2019-03-01 00:00:00+00:00\' and dateid < dateadd(month, 1, \'2019-03-01 00:00:00+00:00\')\n    ;\n    ', ())

During handling of the above exception, another exception occurred:

Traceback (most recent call last):
  File "/home/airflow/.local/lib/python3.12/site-packages/airflow/models/taskinstance.py", line 465, in _execute_task
    result = _execute_callable(context=context, **execute_callable_kwargs)
             ^^^^^^^^^^^^^^^^^^^^^^^^^^^^^^^^^^^^^^^^^^^^^^^^^^^^^^^^^^^^^
  File "/home/airflow/.local/lib/python3.12/site-packages/airflow/models/taskinstance.py", line 432, in _execute_callable
    return execute_callable(context=context, **execute_callable_kwargs)
           ^^^^^^^^^^^^^^^^^^^^^^^^^^^^^^^^^^^^^^^^^^^^^^^^^^^^^^^^^^^^
  File "/home/airflow/.local/lib/python3.12/site-packages/airflow/models/baseoperator.py", line 400, in wrapper
    return func(self, *args, **kwargs)
           ^^^^^^^^^^^^^^^^^^^^^^^^^^^
  File "/home/airflow/.local/lib/python3.12/site-packages/airflow/operators/python.py", line 235, in execute
    return_value = self.execute_callable()
                   ^^^^^^^^^^^^^^^^^^^^^^^
  File "/home/airflow/.local/lib/python3.12/site-packages/airflow/operators/python.py", line 252, in execute_callable
    return self.python_callable(*self.op_args, **self.op_kwargs)
           ^^^^^^^^^^^^^^^^^^^^^^^^^^^^^^^^^^^^^^^^^^^^^^^^^^^^^
  File "/opt/airflow/dags/chess_dag.py", line 31, in redshift_move_task
    return load_move_data(execution_date)
           ^^^^^^^^^^^^^^^^^^^^^^^^^^^^^^
  File "/opt/airflow/dags/redshift_etl_code.py", line 165, in load_move_data
    cursor.execute(delete_moves_staging_query)
  File "/home/airflow/.local/lib/python3.12/site-packages/redshift_connector/cursor.py", line 248, in execute
    raise e
  File "/home/airflow/.local/lib/python3.12/site-packages/redshift_connector/cursor.py", line 241, in execute
    self._c.execute(self, operation, args)
  File "/home/airflow/.local/lib/python3.12/site-packages/redshift_connector/core.py", line 1902, in execute
    self.handle_messages(cursor)
  File "/home/airflow/.local/lib/python3.12/site-packages/redshift_connector/core.py", line 2194, in handle_messages
    raise self.error
redshift_connector.error.ProgrammingError: {'S': 'ERROR', 'C': '42P01', 'M': 'relation "chess_project_staging.move" does not exist', 'F': '../src/pg/src/backend/catalog/namespace.c', 'L': '242', 'R': 'LocalRangeVarGetRelid'}
[2024-07-07T21:05:24.525+0000] {taskinstance.py:1206} INFO - Marking task as FAILED. dag_id=chess_etl, task_id=redshift_move_load, run_id=backfill__2019-03-01T00:00:00+00:00, execution_date=20190301T000000, start_date=20240707T210522, end_date=20240707T210524
[2024-07-07T21:05:24.532+0000] {standard_task_runner.py:110} ERROR - Failed to execute job 543 for task redshift_move_load ({'S': 'ERROR', 'C': '42P01', 'M': 'relation "chess_project_staging.move" does not exist', 'F': '../src/pg/src/backend/catalog/namespace.c', 'L': '242', 'R': 'LocalRangeVarGetRelid'}; 847)
[2024-07-07T21:05:24.555+0000] {local_task_job_runner.py:240} INFO - Task exited with return code 1
[2024-07-07T21:05:24.568+0000] {taskinstance.py:3498} INFO - 0 downstream tasks scheduled from follow-on schedule check
[2024-07-07T21:05:24.569+0000] {local_task_job_runner.py:222} INFO - ::endgroup::
