[2024-07-07T17:48:36.206+0000] {local_task_job_runner.py:120} INFO - ::group::Pre task execution logs
[2024-07-07T17:48:36.220+0000] {taskinstance.py:2076} INFO - Dependencies all met for dep_context=non-requeueable deps ti=<TaskInstance: chess_etl.redshift_etl scheduled__2019-04-01T00:00:00+00:00 [queued]>
[2024-07-07T17:48:36.225+0000] {taskinstance.py:2076} INFO - Dependencies all met for dep_context=requeueable deps ti=<TaskInstance: chess_etl.redshift_etl scheduled__2019-04-01T00:00:00+00:00 [queued]>
[2024-07-07T17:48:36.226+0000] {taskinstance.py:2306} INFO - Starting attempt 1 of 1
[2024-07-07T17:48:36.235+0000] {taskinstance.py:2330} INFO - Executing <Task(PythonOperator): redshift_etl> on 2019-04-01 00:00:00+00:00
[2024-07-07T17:48:36.240+0000] {warnings.py:110} WARNING - /home/***/.local/lib/python3.12/site-packages/***/task/task_runner/standard_task_runner.py:61: DeprecationWarning: This process (pid=544) is multi-threaded, use of fork() may lead to deadlocks in the child.
  pid = os.fork()

[2024-07-07T17:48:36.241+0000] {standard_task_runner.py:63} INFO - Started process 549 to run task
[2024-07-07T17:48:36.241+0000] {standard_task_runner.py:90} INFO - Running: ['***', 'tasks', 'run', 'chess_etl', 'redshift_etl', 'scheduled__2019-04-01T00:00:00+00:00', '--job-id', '380', '--pool', 'default_pool', '--raw', '--subdir', 'DAGS_FOLDER/chess_dag.py', '--cfg-path', '/tmp/tmp6l5apyqz']
[2024-07-07T17:48:36.242+0000] {standard_task_runner.py:91} INFO - Job 380: Subtask redshift_etl
[2024-07-07T17:48:36.276+0000] {task_command.py:426} INFO - Running <TaskInstance: chess_etl.redshift_etl scheduled__2019-04-01T00:00:00+00:00 [running]> on host cb919e35e0e9
[2024-07-07T17:48:36.334+0000] {taskinstance.py:2648} INFO - Exporting env vars: AIRFLOW_CTX_DAG_OWNER='***' AIRFLOW_CTX_DAG_ID='chess_etl' AIRFLOW_CTX_TASK_ID='redshift_etl' AIRFLOW_CTX_EXECUTION_DATE='2019-04-01T00:00:00+00:00' AIRFLOW_CTX_TRY_NUMBER='1' AIRFLOW_CTX_DAG_RUN_ID='scheduled__2019-04-01T00:00:00+00:00'
[2024-07-07T17:48:36.335+0000] {taskinstance.py:430} INFO - ::endgroup::
[2024-07-07T17:48:36.340+0000] {base.py:84} INFO - Using connection ID 'chess_project_redshift' for task execution.
[2024-07-07T17:48:36.907+0000] {warnings.py:110} WARNING - /home/***/.local/lib/python3.12/site-packages/***/utils/context.py:320: AirflowContextDeprecationWarning: Accessing 'execution_date' from the template is deprecated and will be removed in a future version. Please use 'data_interval_start' or 'logical_date' instead.
  warnings.warn(_create_deprecation_warning(k, replacements))

[2024-07-07T17:48:37.501+0000] {taskinstance.py:441} INFO - ::group::Post task execution logs
[2024-07-07T17:48:37.502+0000] {taskinstance.py:2905} ERROR - Task failed with exception
Traceback (most recent call last):
  File "/home/airflow/.local/lib/python3.12/site-packages/airflow/models/taskinstance.py", line 465, in _execute_task
    result = _execute_callable(context=context, **execute_callable_kwargs)
             ^^^^^^^^^^^^^^^^^^^^^^^^^^^^^^^^^^^^^^^^^^^^^^^^^^^^^^^^^^^^^
  File "/home/airflow/.local/lib/python3.12/site-packages/airflow/models/taskinstance.py", line 432, in _execute_callable
    return execute_callable(context=context, **execute_callable_kwargs)
           ^^^^^^^^^^^^^^^^^^^^^^^^^^^^^^^^^^^^^^^^^^^^^^^^^^^^^^^^^^^^
  File "/home/airflow/.local/lib/python3.12/site-packages/airflow/models/baseoperator.py", line 400, in wrapper
    return func(self, *args, **kwargs)
           ^^^^^^^^^^^^^^^^^^^^^^^^^^^
  File "/home/airflow/.local/lib/python3.12/site-packages/airflow/operators/python.py", line 235, in execute
    return_value = self.execute_callable()
                   ^^^^^^^^^^^^^^^^^^^^^^^
  File "/home/airflow/.local/lib/python3.12/site-packages/airflow/operators/python.py", line 252, in execute_callable
    return self.python_callable(*self.op_args, **self.op_kwargs)
           ^^^^^^^^^^^^^^^^^^^^^^^^^^^^^^^^^^^^^^^^^^^^^^^^^^^^^
  File "/opt/airflow/dags/chess_dag.py", line 27, in redshift_etl_task
    return load_game_data(execution_date)
           ^^^^^^^^^^^^^^^^^^^^^^^^^^^^^^
  File "/opt/airflow/dags/redshift_etl_code.py", line 97, in load_game_data
    cursor.execute(copy_games_staging_query)
  File "/home/airflow/.local/lib/python3.12/site-packages/redshift_connector/cursor.py", line 248, in execute
    raise e
  File "/home/airflow/.local/lib/python3.12/site-packages/redshift_connector/cursor.py", line 241, in execute
    self._c.execute(self, operation, args)
  File "/home/airflow/.local/lib/python3.12/site-packages/redshift_connector/core.py", line 1987, in execute
    self.handle_messages(cursor)
  File "/home/airflow/.local/lib/python3.12/site-packages/redshift_connector/core.py", line 2194, in handle_messages
    raise self.error
redshift_connector.error.ProgrammingError: {'S': 'ERROR', 'C': 'XX000', 'M': "The specified S3 prefix '2019_04_games.csv' does not exist", 'D': "\n  -----------------------------------------------\n  error:  The specified S3 prefix '2019_04_games.csv' does not exist\n  code:      8001\n  context:   \n  query:     2035439[child_sequence:1]\n  location:  s3_utility.cpp:710\n  process:   padbmaster [pid=1073881210]\n  -----------------------------------------------\n", 'F': '../src/sys/xen_execute.cpp', 'L': '12618', 'R': 'pg_throw'}
[2024-07-07T17:48:37.510+0000] {taskinstance.py:1206} INFO - Marking task as FAILED. dag_id=chess_etl, task_id=redshift_etl, run_id=scheduled__2019-04-01T00:00:00+00:00, execution_date=20190401T000000, start_date=20240707T174836, end_date=20240707T174837
[2024-07-07T17:48:37.520+0000] {standard_task_runner.py:110} ERROR - Failed to execute job 380 for task redshift_etl ({'S': 'ERROR', 'C': 'XX000', 'M': "The specified S3 prefix '2019_04_games.csv' does not exist", 'D': "\n  -----------------------------------------------\n  error:  The specified S3 prefix '2019_04_games.csv' does not exist\n  code:      8001\n  context:   \n  query:     2035439[child_sequence:1]\n  location:  s3_utility.cpp:710\n  process:   padbmaster [pid=1073881210]\n  -----------------------------------------------\n", 'F': '../src/sys/xen_execute.cpp', 'L': '12618', 'R': 'pg_throw'}; 549)
[2024-07-07T17:48:37.538+0000] {local_task_job_runner.py:240} INFO - Task exited with return code 1
[2024-07-07T17:48:37.551+0000] {taskinstance.py:3498} INFO - 0 downstream tasks scheduled from follow-on schedule check
[2024-07-07T17:48:37.552+0000] {local_task_job_runner.py:222} INFO - ::endgroup::
