[2024-06-08T15:03:04.196+0000] {task_context_logger.py:104} WARNING - Marking task instance <TaskInstance: chess_etl.blunders_etl scheduled__2020-04-01T00:00:00+00:00 [queued]> stuck in queued as failed. If the task instance has available retries, it will be retried.
[2024-06-08T15:03:04.291+0000] {task_context_logger.py:104} ERROR - Executor reports task instance <TaskInstance: chess_etl.blunders_etl scheduled__2020-04-01T00:00:00+00:00 [queued]> finished (failed) although the task says it's queued. (Info: None) Was the task killed externally?
