[2024-07-07T17:52:02.651+0000] {local_task_job_runner.py:120} INFO - ::group::Pre task execution logs
[2024-07-07T17:52:02.665+0000] {taskinstance.py:2076} INFO - Dependencies all met for dep_context=non-requeueable deps ti=<TaskInstance: chess_etl.redshift_etl scheduled__2019-06-01T00:00:00+00:00 [queued]>
[2024-07-07T17:52:02.670+0000] {taskinstance.py:2076} INFO - Dependencies all met for dep_context=requeueable deps ti=<TaskInstance: chess_etl.redshift_etl scheduled__2019-06-01T00:00:00+00:00 [queued]>
[2024-07-07T17:52:02.671+0000] {taskinstance.py:2306} INFO - Starting attempt 1 of 1
[2024-07-07T17:52:02.680+0000] {taskinstance.py:2330} INFO - Executing <Task(PythonOperator): redshift_etl> on 2019-06-01 00:00:00+00:00
[2024-07-07T17:52:02.684+0000] {warnings.py:110} WARNING - /home/***/.local/lib/python3.12/site-packages/***/task/task_runner/standard_task_runner.py:61: DeprecationWarning: This process (pid=592) is multi-threaded, use of fork() may lead to deadlocks in the child.
  pid = os.fork()

[2024-07-07T17:52:02.686+0000] {standard_task_runner.py:63} INFO - Started process 597 to run task
[2024-07-07T17:52:02.685+0000] {standard_task_runner.py:90} INFO - Running: ['***', 'tasks', 'run', 'chess_etl', 'redshift_etl', 'scheduled__2019-06-01T00:00:00+00:00', '--job-id', '383', '--pool', 'default_pool', '--raw', '--subdir', 'DAGS_FOLDER/chess_dag.py', '--cfg-path', '/tmp/tmpd7n92p8_']
[2024-07-07T17:52:02.686+0000] {standard_task_runner.py:91} INFO - Job 383: Subtask redshift_etl
[2024-07-07T17:52:02.720+0000] {task_command.py:426} INFO - Running <TaskInstance: chess_etl.redshift_etl scheduled__2019-06-01T00:00:00+00:00 [running]> on host cb919e35e0e9
[2024-07-07T17:52:02.780+0000] {taskinstance.py:2648} INFO - Exporting env vars: AIRFLOW_CTX_DAG_OWNER='***' AIRFLOW_CTX_DAG_ID='chess_etl' AIRFLOW_CTX_TASK_ID='redshift_etl' AIRFLOW_CTX_EXECUTION_DATE='2019-06-01T00:00:00+00:00' AIRFLOW_CTX_TRY_NUMBER='1' AIRFLOW_CTX_DAG_RUN_ID='scheduled__2019-06-01T00:00:00+00:00'
[2024-07-07T17:52:02.782+0000] {taskinstance.py:430} INFO - ::endgroup::
[2024-07-07T17:52:02.788+0000] {base.py:84} INFO - Using connection ID 'chess_project_s3' for task execution.
[2024-07-07T17:52:02.790+0000] {taskinstance.py:441} INFO - ::group::Post task execution logs
[2024-07-07T17:52:02.791+0000] {taskinstance.py:2905} ERROR - Task failed with exception
Traceback (most recent call last):
  File "/opt/airflow/dags/redshift_etl_code.py", line 12, in load_game_data
    with s3.open(f's3://chess-coach-de-project/{year_month}_games.csv', 'r') as f:
                                                ^^^^^^^^^^
UnboundLocalError: cannot access local variable 'year_month' where it is not associated with a value

During handling of the above exception, another exception occurred:

Traceback (most recent call last):
  File "/home/airflow/.local/lib/python3.12/site-packages/airflow/models/taskinstance.py", line 465, in _execute_task
    result = _execute_callable(context=context, **execute_callable_kwargs)
             ^^^^^^^^^^^^^^^^^^^^^^^^^^^^^^^^^^^^^^^^^^^^^^^^^^^^^^^^^^^^^
  File "/home/airflow/.local/lib/python3.12/site-packages/airflow/models/taskinstance.py", line 432, in _execute_callable
    return execute_callable(context=context, **execute_callable_kwargs)
           ^^^^^^^^^^^^^^^^^^^^^^^^^^^^^^^^^^^^^^^^^^^^^^^^^^^^^^^^^^^^
  File "/home/airflow/.local/lib/python3.12/site-packages/airflow/models/baseoperator.py", line 400, in wrapper
    return func(self, *args, **kwargs)
           ^^^^^^^^^^^^^^^^^^^^^^^^^^^
  File "/home/airflow/.local/lib/python3.12/site-packages/airflow/operators/python.py", line 235, in execute
    return_value = self.execute_callable()
                   ^^^^^^^^^^^^^^^^^^^^^^^
  File "/home/airflow/.local/lib/python3.12/site-packages/airflow/operators/python.py", line 252, in execute_callable
    return self.python_callable(*self.op_args, **self.op_kwargs)
           ^^^^^^^^^^^^^^^^^^^^^^^^^^^^^^^^^^^^^^^^^^^^^^^^^^^^^
  File "/opt/airflow/dags/chess_dag.py", line 27, in redshift_etl_task
    return load_game_data(execution_date)
           ^^^^^^^^^^^^^^^^^^^^^^^^^^^^^^
  File "/opt/airflow/dags/redshift_etl_code.py", line 15, in load_game_data
    print(f'No games for period {year_month}')
                                 ^^^^^^^^^^
UnboundLocalError: cannot access local variable 'year_month' where it is not associated with a value
[2024-07-07T17:52:02.800+0000] {taskinstance.py:1206} INFO - Marking task as FAILED. dag_id=chess_etl, task_id=redshift_etl, run_id=scheduled__2019-06-01T00:00:00+00:00, execution_date=20190601T000000, start_date=20240707T175202, end_date=20240707T175202
[2024-07-07T17:52:02.809+0000] {standard_task_runner.py:110} ERROR - Failed to execute job 383 for task redshift_etl (cannot access local variable 'year_month' where it is not associated with a value; 597)
[2024-07-07T17:52:02.819+0000] {local_task_job_runner.py:240} INFO - Task exited with return code 1
[2024-07-07T17:52:02.830+0000] {taskinstance.py:3498} INFO - 0 downstream tasks scheduled from follow-on schedule check
[2024-07-07T17:52:02.832+0000] {local_task_job_runner.py:222} INFO - ::endgroup::
